I tensorflow/stream_executor/dso_loader.cc:108] successfully opened CUDA library libcublas.so locally
I tensorflow/stream_executor/dso_loader.cc:108] successfully opened CUDA library libcudnn.so locally
I tensorflow/stream_executor/dso_loader.cc:108] successfully opened CUDA library libcufft.so locally
I tensorflow/stream_executor/dso_loader.cc:108] successfully opened CUDA library libcuda.so.1 locally
I tensorflow/stream_executor/dso_loader.cc:108] successfully opened CUDA library libcurand.so locally
I tensorflow/core/common_runtime/gpu/gpu_init.cc:102] Found device 0 with properties: 
name: GeForce GTX 960
major: 5 minor: 2 memoryClockRate (GHz) 1.253
pciBusID 0000:03:00.0
Total memory: 4.00GiB
Free memory: 3.77GiB
I tensorflow/core/common_runtime/gpu/gpu_init.cc:126] DMA: 0 
I tensorflow/core/common_runtime/gpu/gpu_init.cc:136] 0:   Y 
I tensorflow/core/common_runtime/gpu/gpu_device.cc:839] Creating TensorFlow device (/gpu:0) -> (device: 0, name: GeForce GTX 960, pci bus id: 0000:03:00.0)
E tensorflow/core/client/tensor_c_api.cc:485] /home/zan/Desktop/NNP/Prostate_Cancer_Data1.bin
	 [[Node: ReaderRead = ReaderRead[_class=["loc:@FixedLengthRecordReader", "loc:@input_producer"], _device="/job:localhost/replica:0/task:0/cpu:0"](FixedLengthRecordReader, input_producer)]]
	 [[Node: Slice_1/_9 = _Recv[client_terminated=false, recv_device="/job:localhost/replica:0/task:0/gpu:0", send_device="/job:localhost/replica:0/task:0/cpu:0", send_device_incarnation=1, tensor_name="edge_9_Slice_1", tensor_type=DT_UINT8, _device="/job:localhost/replica:0/task:0/gpu:0"]()]]
ERROR:tensorflow:Exception in QueueRunner: /home/zan/Desktop/NNP/Prostate_Cancer_Data1.bin
	 [[Node: ReaderRead = ReaderRead[_class=["loc:@FixedLengthRecordReader", "loc:@input_producer"], _device="/job:localhost/replica:0/task:0/cpu:0"](FixedLengthRecordReader, input_producer)]]
	 [[Node: Slice_1/_9 = _Recv[client_terminated=false, recv_device="/job:localhost/replica:0/task:0/gpu:0", send_device="/job:localhost/replica:0/task:0/cpu:0", send_device_incarnation=1, tensor_name="edge_9_Slice_1", tensor_type=DT_UINT8, _device="/job:localhost/replica:0/task:0/gpu:0"]()]]
Caused by op u'ReaderRead', defined at:
  File "eval.py", line 33, in <module>
    tf.app.run()
  File "/usr/local/lib/python2.7/dist-packages/tensorflow/python/platform/app.py", line 30, in run
    sys.exit(main(sys.argv))
  File "eval.py", line 30, in main
    evaluate()
  File "eval.py", line 13, in evaluate
    images, labels = Process.eval_inputs()
  File "/home/zan/Desktop/NNP/Process.py", line 35, in eval_inputs
    images, labels = Input.eval_inputs(data_dir = data_dir, batch_size = 1)
  File "/home/zan/Desktop/NNP/Input.py", line 92, in eval_inputs
    read_input = read_data(filename_queue)
  File "/home/zan/Desktop/NNP/Input.py", line 32, in read_data
    result.key, value = reader.read(filename_queue)
  File "/usr/local/lib/python2.7/dist-packages/tensorflow/python/ops/io_ops.py", line 334, in read
    return gen_io_ops._reader_read(self._reader_ref, queue_ref, name=name)
  File "/usr/local/lib/python2.7/dist-packages/tensorflow/python/ops/gen_io_ops.py", line 176, in _reader_read
    queue_handle=queue_handle, name=name)
  File "/usr/local/lib/python2.7/dist-packages/tensorflow/python/framework/op_def_library.py", line 703, in apply_op
    op_def=op_def)
  File "/usr/local/lib/python2.7/dist-packages/tensorflow/python/framework/ops.py", line 2310, in create_op
    original_op=self._default_original_op, op_def=op_def)
  File "/usr/local/lib/python2.7/dist-packages/tensorflow/python/framework/ops.py", line 1232, in __init__
    self._traceback = _extract_stack()

Exception in thread Thread-2:
Traceback (most recent call last):
  File "/usr/lib/python2.7/threading.py", line 801, in __bootstrap_inner
    self.run()
  File "/usr/lib/python2.7/threading.py", line 754, in run
    self.__target(*self.__args, **self.__kwargs)
  File "/usr/local/lib/python2.7/dist-packages/tensorflow/python/training/queue_runner.py", line 185, in _run
    sess.run(enqueue_op)
  File "/usr/local/lib/python2.7/dist-packages/tensorflow/python/client/session.py", line 382, in run
    run_metadata_ptr)
  File "/usr/local/lib/python2.7/dist-packages/tensorflow/python/client/session.py", line 655, in _run
    feed_dict_string, options, run_metadata)
  File "/usr/local/lib/python2.7/dist-packages/tensorflow/python/client/session.py", line 723, in _do_run
    target_list, options, run_metadata)
  File "/usr/local/lib/python2.7/dist-packages/tensorflow/python/client/session.py", line 743, in _do_call
    raise type(e)(node_def, op, message)
NotFoundError: /home/zan/Desktop/NNP/Prostate_Cancer_Data1.bin
	 [[Node: ReaderRead = ReaderRead[_class=["loc:@FixedLengthRecordReader", "loc:@input_producer"], _device="/job:localhost/replica:0/task:0/cpu:0"](FixedLengthRecordReader, input_producer)]]
	 [[Node: Slice_1/_9 = _Recv[client_terminated=false, recv_device="/job:localhost/replica:0/task:0/gpu:0", send_device="/job:localhost/replica:0/task:0/cpu:0", send_device_incarnation=1, tensor_name="edge_9_Slice_1", tensor_type=DT_UINT8, _device="/job:localhost/replica:0/task:0/gpu:0"]()]]
Caused by op u'ReaderRead', defined at:
  File "eval.py", line 33, in <module>
    tf.app.run()
  File "/usr/local/lib/python2.7/dist-packages/tensorflow/python/platform/app.py", line 30, in run
    sys.exit(main(sys.argv))
  File "eval.py", line 30, in main
    evaluate()
  File "eval.py", line 13, in evaluate
    images, labels = Process.eval_inputs()
  File "/home/zan/Desktop/NNP/Process.py", line 35, in eval_inputs
    images, labels = Input.eval_inputs(data_dir = data_dir, batch_size = 1)
  File "/home/zan/Desktop/NNP/Input.py", line 92, in eval_inputs
    read_input = read_data(filename_queue)
  File "/home/zan/Desktop/NNP/Input.py", line 32, in read_data
    result.key, value = reader.read(filename_queue)
  File "/usr/local/lib/python2.7/dist-packages/tensorflow/python/ops/io_ops.py", line 334, in read
    return gen_io_ops._reader_read(self._reader_ref, queue_ref, name=name)
  File "/usr/local/lib/python2.7/dist-packages/tensorflow/python/ops/gen_io_ops.py", line 176, in _reader_read
    queue_handle=queue_handle, name=name)
  File "/usr/local/lib/python2.7/dist-packages/tensorflow/python/framework/op_def_library.py", line 703, in apply_op
    op_def=op_def)
  File "/usr/local/lib/python2.7/dist-packages/tensorflow/python/framework/ops.py", line 2310, in create_op
    original_op=self._default_original_op, op_def=op_def)
  File "/usr/local/lib/python2.7/dist-packages/tensorflow/python/framework/ops.py", line 1232, in __init__
    self._traceback = _extract_stack()


E tensorflow/core/client/tensor_c_api.cc:485] /home/zan/Desktop/NNP/Prostate_Cancer_Data1.bin
	 [[Node: ReaderRead = ReaderRead[_class=["loc:@FixedLengthRecordReader", "loc:@input_producer"], _device="/job:localhost/replica:0/task:0/cpu:0"](FixedLengthRecordReader, input_producer)]]
	 [[Node: Slice_1/_9 = _Recv[client_terminated=false, recv_device="/job:localhost/replica:0/task:0/gpu:0", send_device="/job:localhost/replica:0/task:0/cpu:0", send_device_incarnation=1, tensor_name="edge_9_Slice_1", tensor_type=DT_UINT8, _device="/job:localhost/replica:0/task:0/gpu:0"]()]]
ERROR:tensorflow:Exception in QueueRunner: /home/zan/Desktop/NNP/Prostate_Cancer_Data1.bin
	 [[Node: ReaderRead = ReaderRead[_class=["loc:@FixedLengthRecordReader", "loc:@input_producer"], _device="/job:localhost/replica:0/task:0/cpu:0"](FixedLengthRecordReader, input_producer)]]
	 [[Node: Slice_1/_9 = _Recv[client_terminated=false, recv_device="/job:localhost/replica:0/task:0/gpu:0", send_device="/job:localhost/replica:0/task:0/cpu:0", send_device_incarnation=1, tensor_name="edge_9_Slice_1", tensor_type=DT_UINT8, _device="/job:localhost/replica:0/task:0/gpu:0"]()]]
Caused by op u'ReaderRead', defined at:
  File "eval.py", line 33, in <module>
    tf.app.run()
  File "/usr/local/lib/python2.7/dist-packages/tensorflow/python/platform/app.py", line 30, in run
    sys.exit(main(sys.argv))
  File "eval.py", line 30, in main
    evaluate()
  File "eval.py", line 13, in evaluate
    images, labels = Process.eval_inputs()
  File "/home/zan/Desktop/NNP/Process.py", line 35, in eval_inputs
    images, labels = Input.eval_inputs(data_dir = data_dir, batch_size = 1)
  File "/home/zan/Desktop/NNP/Input.py", line 92, in eval_inputs
    read_input = read_data(filename_queue)
  File "/home/zan/Desktop/NNP/Input.py", line 32, in read_data
    result.key, value = reader.read(filename_queue)
  File "/usr/local/lib/python2.7/dist-packages/tensorflow/python/ops/io_ops.py", line 334, in read
    return gen_io_ops._reader_read(self._reader_ref, queue_ref, name=name)
  File "/usr/local/lib/python2.7/dist-packages/tensorflow/python/ops/gen_io_ops.py", line 176, in _reader_read
    queue_handle=queue_handle, name=name)
  File "/usr/local/lib/python2.7/dist-packages/tensorflow/python/framework/op_def_library.py", line 703, in apply_op
    op_def=op_def)
  File "/usr/local/lib/python2.7/dist-packages/tensorflow/python/framework/ops.py", line 2310, in create_op
    original_op=self._default_original_op, op_def=op_def)
  File "/usr/local/lib/python2.7/dist-packages/tensorflow/python/framework/ops.py", line 1232, in __init__
    self._traceback = _extract_stack()

Exception in thread Thread-6:
Traceback (most recent call last):
  File "/usr/lib/python2.7/threading.py", line 801, in __bootstrap_inner
    self.run()
  File "/usr/lib/python2.7/threading.py", line 754, in run
    self.__target(*self.__args, **self.__kwargs)
  File "/usr/local/lib/python2.7/dist-packages/tensorflow/python/training/queue_runner.py", line 185, in _run
    sess.run(enqueue_op)
  File "/usr/local/lib/python2.7/dist-packages/tensorflow/python/client/session.py", line 382, in run
    run_metadata_ptr)
  File "/usr/local/lib/python2.7/dist-packages/tensorflow/python/client/session.py", line 655, in _run
    feed_dict_string, options, run_metadata)
  File "/usr/local/lib/python2.7/dist-packages/tensorflow/python/client/session.py", line 723, in _do_run
    target_list, options, run_metadata)
  File "/usr/local/lib/python2.7/dist-packages/tensorflow/python/client/session.py", line 743, in _do_call
    raise type(e)(node_def, op, message)
NotFoundError: /home/zan/Desktop/NNP/Prostate_Cancer_Data1.bin
	 [[Node: ReaderRead = ReaderRead[_class=["loc:@FixedLengthRecordReader", "loc:@input_producer"], _device="/job:localhost/replica:0/task:0/cpu:0"](FixedLengthRecordReader, input_producer)]]
	 [[Node: Slice_1/_9 = _Recv[client_terminated=false, recv_device="/job:localhost/replica:0/task:0/gpu:0", send_device="/job:localhost/replica:0/task:0/cpu:0", send_device_incarnation=1, tensor_name="edge_9_Slice_1", tensor_type=DT_UINT8, _device="/job:localhost/replica:0/task:0/gpu:0"]()]]
Caused by op u'ReaderRead', defined at:
  File "eval.py", line 33, in <module>
    tf.app.run()
  File "/usr/local/lib/python2.7/dist-packages/tensorflow/python/platform/app.py", line 30, in run
    sys.exit(main(sys.argv))
  File "eval.py", line 30, in main
    evaluate()
  File "eval.py", line 13, in evaluate
    images, labels = Process.eval_inputs()
  File "/home/zan/Desktop/NNP/Process.py", line 35, in eval_inputs
    images, labels = Input.eval_inputs(data_dir = data_dir, batch_size = 1)
  File "/home/zan/Desktop/NNP/Input.py", line 92, in eval_inputs
    read_input = read_data(filename_queue)
  File "/home/zan/Desktop/NNP/Input.py", line 32, in read_data
    result.key, value = reader.read(filename_queue)
  File "/usr/local/lib/python2.7/dist-packages/tensorflow/python/ops/io_ops.py", line 334, in read
    return gen_io_ops._reader_read(self._reader_ref, queue_ref, name=name)
  File "/usr/local/lib/python2.7/dist-packages/tensorflow/python/ops/gen_io_ops.py", line 176, in _reader_read
    queue_handle=queue_handle, name=name)
  File "/usr/local/lib/python2.7/dist-packages/tensorflow/python/framework/op_def_library.py", line 703, in apply_op
    op_def=op_def)
  File "/usr/local/lib/python2.7/dist-packages/tensorflow/python/framework/ops.py", line 2310, in create_op
    original_op=self._default_original_op, op_def=op_def)
  File "/usr/local/lib/python2.7/dist-packages/tensorflow/python/framework/ops.py", line 1232, in __init__
    self._traceback = _extract_stack()


E tensorflow/core/client/tensor_c_api.cc:485] /home/zan/Desktop/NNP/Prostate_Cancer_Data1.bin
	 [[Node: ReaderRead = ReaderRead[_class=["loc:@FixedLengthRecordReader", "loc:@input_producer"], _device="/job:localhost/replica:0/task:0/cpu:0"](FixedLengthRecordReader, input_producer)]]
	 [[Node: Slice/_11 = _Recv[client_terminated=false, recv_device="/job:localhost/replica:0/task:0/gpu:0", send_device="/job:localhost/replica:0/task:0/cpu:0", send_device_incarnation=1, tensor_name="edge_17_Slice", tensor_type=DT_UINT8, _device="/job:localhost/replica:0/task:0/gpu:0"]()]]
ERROR:tensorflow:Exception in QueueRunner: /home/zan/Desktop/NNP/Prostate_Cancer_Data1.bin
	 [[Node: ReaderRead = ReaderRead[_class=["loc:@FixedLengthRecordReader", "loc:@input_producer"], _device="/job:localhost/replica:0/task:0/cpu:0"](FixedLengthRecordReader, input_producer)]]
	 [[Node: Slice/_11 = _Recv[client_terminated=false, recv_device="/job:localhost/replica:0/task:0/gpu:0", send_device="/job:localhost/replica:0/task:0/cpu:0", send_device_incarnation=1, tensor_name="edge_17_Slice", tensor_type=DT_UINT8, _device="/job:localhost/replica:0/task:0/gpu:0"]()]]
Caused by op u'ReaderRead', defined at:
  File "eval.py", line 33, in <module>
    tf.app.run()
  File "/usr/local/lib/python2.7/dist-packages/tensorflow/python/platform/app.py", line 30, in run
    sys.exit(main(sys.argv))
  File "eval.py", line 30, in main
    evaluate()
  File "eval.py", line 13, in evaluate
    images, labels = Process.eval_inputs()
  File "/home/zan/Desktop/NNP/Process.py", line 35, in eval_inputs
    images, labels = Input.eval_inputs(data_dir = data_dir, batch_size = 1)
  File "/home/zan/Desktop/NNP/Input.py", line 92, in eval_inputs
    read_input = read_data(filename_queue)
  File "/home/zan/Desktop/NNP/Input.py", line 32, in read_data
    result.key, value = reader.read(filename_queue)
  File "/usr/local/lib/python2.7/dist-packages/tensorflow/python/ops/io_ops.py", line 334, in read
    return gen_io_ops._reader_read(self._reader_ref, queue_ref, name=name)
  File "/usr/local/lib/python2.7/dist-packages/tensorflow/python/ops/gen_io_ops.py", line 176, in _reader_read
    queue_handle=queue_handle, name=name)
  File "/usr/local/lib/python2.7/dist-packages/tensorflow/python/framework/op_def_library.py", line 703, in apply_op
    op_def=op_def)
  File "/usr/local/lib/python2.7/dist-packages/tensorflow/python/framework/ops.py", line 2310, in create_op
    original_op=self._default_original_op, op_def=op_def)
  File "/usr/local/lib/python2.7/dist-packages/tensorflow/python/framework/ops.py", line 1232, in __init__
    self._traceback = _extract_stack()

E tensorflow/core/client/tensor_c_api.cc:485] /home/zan/Desktop/NNP/Prostate_Cancer_Data1.bin
	 [[Node: ReaderRead = ReaderRead[_class=["loc:@FixedLengthRecordReader", "loc:@input_producer"], _device="/job:localhost/replica:0/task:0/cpu:0"](FixedLengthRecordReader, input_producer)]]
	 [[Node: Slice/_11 = _Recv[client_terminated=false, recv_device="/job:localhost/replica:0/task:0/gpu:0", send_device="/job:localhost/replica:0/task:0/cpu:0", send_device_incarnation=1, tensor_name="edge_17_Slice", tensor_type=DT_UINT8, _device="/job:localhost/replica:0/task:0/gpu:0"]()]]
E tensorflow/core/client/tensor_c_api.cc:485] /home/zan/Desktop/NNP/Prostate_Cancer_Data1.bin
	 [[Node: ReaderRead = ReaderRead[_class=["loc:@FixedLengthRecordReader", "loc:@input_producer"], _device="/job:localhost/replica:0/task:0/cpu:0"](FixedLengthRecordReader, input_producer)]]
	 [[Node: Slice_1/_9 = _Recv[client_terminated=false, recv_device="/job:localhost/replica:0/task:0/gpu:0", send_device="/job:localhost/replica:0/task:0/cpu:0", send_device_incarnation=1, tensor_name="edge_9_Slice_1", tensor_type=DT_UINT8, _device="/job:localhost/replica:0/task:0/gpu:0"]()]]
E tensorflow/core/client/tensor_c_api.cc:485] /home/zan/Desktop/NNP/Prostate_Cancer_Data1.bin
	 [[Node: ReaderRead = ReaderRead[_class=["loc:@FixedLengthRecordReader", "loc:@input_producer"], _device="/job:localhost/replica:0/task:0/cpu:0"](FixedLengthRecordReader, input_producer)]]
	 [[Node: Slice/_11 = _Recv[client_terminated=false, recv_device="/job:localhost/replica:0/task:0/gpu:0", send_device="/job:localhost/replica:0/task:0/cpu:0", send_device_incarnation=1, tensor_name="edge_17_Slice", tensor_type=DT_UINT8, _device="/job:localhost/replica:0/task:0/gpu:0"]()]]
Exception in thread Thread-9:
Traceback (most recent call last):
  File "/usr/lib/python2.7/threading.py", line 801, in __bootstrap_inner
    self.run()
  File "/usr/lib/python2.7/threading.py", line 754, in run
    self.__target(*self.__args, **self.__kwargs)
  File "/usr/local/lib/python2.7/dist-packages/tensorflow/python/training/queue_runner.py", line 185, in _run
    sess.run(enqueue_op)
  File "/usr/local/lib/python2.7/dist-packages/tensorflow/python/client/session.py", line 382, in run
    run_metadata_ptr)
  File "/usr/local/lib/python2.7/dist-packages/tensorflow/python/client/session.py", line 655, in _run
    feed_dict_string, options, run_metadata)
  File "/usr/local/lib/python2.7/dist-packages/tensorflow/python/client/session.py", line 723, in _do_run
    target_list, options, run_metadata)
  File "/usr/local/lib/python2.7/dist-packages/tensorflow/python/client/session.py", line 743, in _do_call
    raise type(e)(node_def, op, message)
NotFoundError: /home/zan/Desktop/NNP/Prostate_Cancer_Data1.bin
	 [[Node: ReaderRead = ReaderRead[_class=["loc:@FixedLengthRecordReader", "loc:@input_producer"], _device="/job:localhost/replica:0/task:0/cpu:0"](FixedLengthRecordReader, input_producer)]]
	 [[Node: Slice/_11 = _Recv[client_terminated=false, recv_device="/job:localhost/replica:0/task:0/gpu:0", send_device="/job:localhost/replica:0/task:0/cpu:0", send_device_incarnation=1, tensor_name="edge_17_Slice", tensor_type=DT_UINT8, _device="/job:localhost/replica:0/task:0/gpu:0"]()]]
Caused by op u'ReaderRead', defined at:
  File "eval.py", line 33, in <module>
    tf.app.run()
  File "/usr/local/lib/python2.7/dist-packages/tensorflow/python/platform/app.py", line 30, in run
    sys.exit(main(sys.argv))
  File "eval.py", line 30, in main
    evaluate()
  File "eval.py", line 13, in evaluate
    images, labels = Process.eval_inputs()
  File "/home/zan/Desktop/NNP/Process.py", line 35, in eval_inputs
    images, labels = Input.eval_inputs(data_dir = data_dir, batch_size = 1)
  File "/home/zan/Desktop/NNP/Input.py", line 92, in eval_inputs
    read_input = read_data(filename_queue)
  File "/home/zan/Desktop/NNP/Input.py", line 32, in read_data
    result.key, value = reader.read(filename_queue)
  File "/usr/local/lib/python2.7/dist-packages/tensorflow/python/ops/io_ops.py", line 334, in read
    return gen_io_ops._reader_read(self._reader_ref, queue_ref, name=name)
  File "/usr/local/lib/python2.7/dist-packages/tensorflow/python/ops/gen_io_ops.py", line 176, in _reader_read
    queue_handle=queue_handle, name=name)
  File "/usr/local/lib/python2.7/dist-packages/tensorflow/python/framework/op_def_library.py", line 703, in apply_op
    op_def=op_def)
  File "/usr/local/lib/python2.7/dist-packages/tensorflow/python/framework/ops.py", line 2310, in create_op
    original_op=self._default_original_op, op_def=op_def)
  File "/usr/local/lib/python2.7/dist-packages/tensorflow/python/framework/ops.py", line 1232, in __init__
    self._traceback = _extract_stack()


E tensorflow/core/client/tensor_c_api.cc:485] /home/zan/Desktop/NNP/Prostate_Cancer_Data1.bin
	 [[Node: ReaderRead = ReaderRead[_class=["loc:@FixedLengthRecordReader", "loc:@input_producer"], _device="/job:localhost/replica:0/task:0/cpu:0"](FixedLengthRecordReader, input_producer)]]
	 [[Node: Slice_1/_9 = _Recv[client_terminated=false, recv_device="/job:localhost/replica:0/task:0/gpu:0", send_device="/job:localhost/replica:0/task:0/cpu:0", send_device_incarnation=1, tensor_name="edge_9_Slice_1", tensor_type=DT_UINT8, _device="/job:localhost/replica:0/task:0/gpu:0"]()]]
ERROR:tensorflow:Exception in QueueRunner: /home/zan/Desktop/NNP/Prostate_Cancer_Data1.bin
	 [[Node: ReaderRead = ReaderRead[_class=["loc:@FixedLengthRecordReader", "loc:@input_producer"], _device="/job:localhost/replica:0/task:0/cpu:0"](FixedLengthRecordReader, input_producer)]]
	 [[Node: Slice/_11 = _Recv[client_terminated=false, recv_device="/job:localhost/replica:0/task:0/gpu:0", send_device="/job:localhost/replica:0/task:0/cpu:0", send_device_incarnation=1, tensor_name="edge_17_Slice", tensor_type=DT_UINT8, _device="/job:localhost/replica:0/task:0/gpu:0"]()]]
Caused by op u'ReaderRead', defined at:
  File "eval.py", line 33, in <module>
    tf.app.run()
  File "/usr/local/lib/python2.7/dist-packages/tensorflow/python/platform/app.py", line 30, in run
    sys.exit(main(sys.argv))
  File "eval.py", line 30, in main
    evaluate()
  File "eval.py", line 13, in evaluate
    images, labels = Process.eval_inputs()
  File "/home/zan/Desktop/NNP/Process.py", line 35, in eval_inputs
    images, labels = Input.eval_inputs(data_dir = data_dir, batch_size = 1)
  File "/home/zan/Desktop/NNP/Input.py", line 92, in eval_inputs
    read_input = read_data(filename_queue)
  File "/home/zan/Desktop/NNP/Input.py", line 32, in read_data
    result.key, value = reader.read(filename_queue)
  File "/usr/local/lib/python2.7/dist-packages/tensorflow/python/ops/io_ops.py", line 334, in read
    return gen_io_ops._reader_read(self._reader_ref, queue_ref, name=name)
  File "/usr/local/lib/python2.7/dist-packages/tensorflow/python/ops/gen_io_ops.py", line 176, in _reader_read
    queue_handle=queue_handle, name=name)
  File "/usr/local/lib/python2.7/dist-packages/tensorflow/python/framework/op_def_library.py", line 703, in apply_op
    op_def=op_def)
  File "/usr/local/lib/python2.7/dist-packages/tensorflow/python/framework/ops.py", line 2310, in create_op
    original_op=self._default_original_op, op_def=op_def)
  File "/usr/local/lib/python2.7/dist-packages/tensorflow/python/framework/ops.py", line 1232, in __init__
    self._traceback = _extract_stack()

ERROR:tensorflow:Exception in QueueRunner: /home/zan/Desktop/NNP/Prostate_Cancer_Data1.bin
	 [[Node: ReaderRead = ReaderRead[_class=["loc:@FixedLengthRecordReader", "loc:@input_producer"], _device="/job:localhost/replica:0/task:0/cpu:0"](FixedLengthRecordReader, input_producer)]]
	 [[Node: Slice/_11 = _Recv[client_terminated=false, recv_device="/job:localhost/replica:0/task:0/gpu:0", send_device="/job:localhost/replica:0/task:0/cpu:0", send_device_incarnation=1, tensor_name="edge_17_Slice", tensor_type=DT_UINT8, _device="/job:localhost/replica:0/task:0/gpu:0"]()]]
Caused by op u'ReaderRead', defined at:
  File "eval.py", line 33, in <module>
    tf.app.run()
  File "/usr/local/lib/python2.7/dist-packages/tensorflow/python/platform/app.py", line 30, in run
    sys.exit(main(sys.argv))
  File "eval.py", line 30, in main
    evaluate()
  File "eval.py", line 13, in evaluate
    images, labels = Process.eval_inputs()
  File "/home/zan/Desktop/NNP/Process.py", line 35, in eval_inputs
    images, labels = Input.eval_inputs(data_dir = data_dir, batch_size = 1)
  File "/home/zan/Desktop/NNP/Input.py", line 92, in eval_inputs
    read_input = read_data(filename_queue)
  File "/home/zan/Desktop/NNP/Input.py", line 32, in read_data
    result.key, value = reader.read(filename_queue)
  File "/usr/local/lib/python2.7/dist-packages/tensorflow/python/ops/io_ops.py", line 334, in read
    return gen_io_ops._reader_read(self._reader_ref, queue_ref, name=name)
  File "/usr/local/lib/python2.7/dist-packages/tensorflow/python/ops/gen_io_ops.py", line 176, in _reader_read
    queue_handle=queue_handle, name=name)
  File "/usr/local/lib/python2.7/dist-packages/tensorflow/python/framework/op_def_library.py", line 703, in apply_op
    op_def=op_def)
  File "/usr/local/lib/python2.7/dist-packages/tensorflow/python/framework/ops.py", line 2310, in create_op
    original_op=self._default_original_op, op_def=op_def)
  File "/usr/local/lib/python2.7/dist-packages/tensorflow/python/framework/ops.py", line 1232, in __init__
    self._traceback = _extract_stack()

ERROR:tensorflow:Exception in QueueRunner: /home/zan/Desktop/NNP/Prostate_Cancer_Data1.bin
	 [[Node: ReaderRead = ReaderRead[_class=["loc:@FixedLengthRecordReader", "loc:@input_producer"], _device="/job:localhost/replica:0/task:0/cpu:0"](FixedLengthRecordReader, input_producer)]]
	 [[Node: Slice_1/_9 = _Recv[client_terminated=false, recv_device="/job:localhost/replica:0/task:0/gpu:0", send_device="/job:localhost/replica:0/task:0/cpu:0", send_device_incarnation=1, tensor_name="edge_9_Slice_1", tensor_type=DT_UINT8, _device="/job:localhost/replica:0/task:0/gpu:0"]()]]
Caused by op u'ReaderRead', defined at:
  File "eval.py", line 33, in <module>
    tf.app.run()
  File "/usr/local/lib/python2.7/dist-packages/tensorflow/python/platform/app.py", line 30, in run
    sys.exit(main(sys.argv))
  File "eval.py", line 30, in main
    evaluate()
  File "eval.py", line 13, in evaluate
    images, labels = Process.eval_inputs()
  File "/home/zan/Desktop/NNP/Process.py", line 35, in eval_inputs
    images, labels = Input.eval_inputs(data_dir = data_dir, batch_size = 1)
  File "/home/zan/Desktop/NNP/Input.py", line 92, in eval_inputs
    read_input = read_data(filename_queue)
  File "/home/zan/Desktop/NNP/Input.py", line 32, in read_data
    result.key, value = reader.read(filename_queue)
  File "/usr/local/lib/python2.7/dist-packages/tensorflow/python/ops/io_ops.py", line 334, in read
    return gen_io_ops._reader_read(self._reader_ref, queue_ref, name=name)
  File "/usr/local/lib/python2.7/dist-packages/tensorflow/python/ops/gen_io_ops.py", line 176, in _reader_read
    queue_handle=queue_handle, name=name)
  File "/usr/local/lib/python2.7/dist-packages/tensorflow/python/framework/op_def_library.py", line 703, in apply_op
    op_def=op_def)
  File "/usr/local/lib/python2.7/dist-packages/tensorflow/python/framework/ops.py", line 2310, in create_op
    original_op=self._default_original_op, op_def=op_def)
  File "/usr/local/lib/python2.7/dist-packages/tensorflow/python/framework/ops.py", line 1232, in __init__
    self._traceback = _extract_stack()

E tensorflow/core/client/tensor_c_api.cc:485] /home/zan/Desktop/NNP/Prostate_Cancer_Data1.bin
	 [[Node: ReaderRead = ReaderRead[_class=["loc:@FixedLengthRecordReader", "loc:@input_producer"], _device="/job:localhost/replica:0/task:0/cpu:0"](FixedLengthRecordReader, input_producer)]]
	 [[Node: Slice/_11 = _Recv[client_terminated=false, recv_device="/job:localhost/replica:0/task:0/gpu:0", send_device="/job:localhost/replica:0/task:0/cpu:0", send_device_incarnation=1, tensor_name="edge_17_Slice", tensor_type=DT_UINT8, _device="/job:localhost/replica:0/task:0/gpu:0"]()]]
Exception in thread Thread-3:
Traceback (most recent call last):
  File "/usr/lib/python2.7/threading.py", line 801, in __bootstrap_inner
    self.run()
  File "/usr/lib/python2.7/threading.py", line 754, in run
    self.__target(*self.__args, **self.__kwargs)
  File "/usr/local/lib/python2.7/dist-packages/tensorflow/python/training/queue_runner.py", line 185, in _run
    sess.run(enqueue_op)
  File "/usr/local/lib/python2.7/dist-packages/tensorflow/python/client/session.py", line 382, in run
    run_metadata_ptr)
  File "/usr/local/lib/python2.7/dist-packages/tensorflow/python/client/session.py", line 655, in _run
    feed_dict_string, options, run_metadata)
  File "/usr/local/lib/python2.7/dist-packages/tensorflow/python/client/session.py", line 723, in _do_run
    target_list, options, run_metadata)
  File "/usr/local/lib/python2.7/dist-packages/tensorflow/python/client/session.py", line 743, in _do_call
    raise type(e)(node_def, op, message)
NotFoundError: /home/zan/Desktop/NNP/Prostate_Cancer_Data1.bin
	 [[Node: ReaderRead = ReaderRead[_class=["loc:@FixedLengthRecordReader", "loc:@input_producer"], _device="/job:localhost/replica:0/task:0/cpu:0"](FixedLengthRecordReader, input_producer)]]
	 [[Node: Slice/_11 = _Recv[client_terminated=false, recv_device="/job:localhost/replica:0/task:0/gpu:0", send_device="/job:localhost/replica:0/task:0/cpu:0", send_device_incarnation=1, tensor_name="edge_17_Slice", tensor_type=DT_UINT8, _device="/job:localhost/replica:0/task:0/gpu:0"]()]]
Caused by op u'ReaderRead', defined at:
  File "eval.py", line 33, in <module>
    tf.app.run()
  File "/usr/local/lib/python2.7/dist-packages/tensorflow/python/platform/app.py", line 30, in run
    sys.exit(main(sys.argv))
  File "eval.py", line 30, in main
    evaluate()
  File "eval.py", line 13, in evaluate
    images, labels = Process.eval_inputs()
  File "/home/zan/Desktop/NNP/Process.py", line 35, in eval_inputs
    images, labels = Input.eval_inputs(data_dir = data_dir, batch_size = 1)
  File "/home/zan/Desktop/NNP/Input.py", line 92, in eval_inputs
    read_input = read_data(filename_queue)
  File "/home/zan/Desktop/NNP/Input.py", line 32, in read_data
    result.key, value = reader.read(filename_queue)
  File "/usr/local/lib/python2.7/dist-packages/tensorflow/python/ops/io_ops.py", line 334, in read
    return gen_io_ops._reader_read(self._reader_ref, queue_ref, name=name)
  File "/usr/local/lib/python2.7/dist-packages/tensorflow/python/ops/gen_io_ops.py", line 176, in _reader_read
    queue_handle=queue_handle, name=name)
  File "/usr/local/lib/python2.7/dist-packages/tensorflow/python/framework/op_def_library.py", line 703, in apply_op
    op_def=op_def)
  File "/usr/local/lib/python2.7/dist-packages/tensorflow/python/framework/ops.py", line 2310, in create_op
    original_op=self._default_original_op, op_def=op_def)
  File "/usr/local/lib/python2.7/dist-packages/tensorflow/python/framework/ops.py", line 1232, in __init__
    self._traceback = _extract_stack()

ERROR:tensorflow:Exception in QueueRunner: /home/zan/Desktop/NNP/Prostate_Cancer_Data1.bin
	 [[Node: ReaderRead = ReaderRead[_class=["loc:@FixedLengthRecordReader", "loc:@input_producer"], _device="/job:localhost/replica:0/task:0/cpu:0"](FixedLengthRecordReader, input_producer)]]
	 [[Node: Slice_1/_9 = _Recv[client_terminated=false, recv_device="/job:localhost/replica:0/task:0/gpu:0", send_device="/job:localhost/replica:0/task:0/cpu:0", send_device_incarnation=1, tensor_name="edge_9_Slice_1", tensor_type=DT_UINT8, _device="/job:localhost/replica:0/task:0/gpu:0"]()]]
Caused by op u'ReaderRead', defined at:
  File "eval.py", line 33, in <module>
    tf.app.run()
  File "/usr/local/lib/python2.7/dist-packages/tensorflow/python/platform/app.py", line 30, in run
    sys.exit(main(sys.argv))
  File "eval.py", line 30, in main
    evaluate()
  File "eval.py", line 13, in evaluate
    images, labels = Process.eval_inputs()
  File "/home/zan/Desktop/NNP/Process.py", line 35, in eval_inputs
    images, labels = Input.eval_inputs(data_dir = data_dir, batch_size = 1)
  File "/home/zan/Desktop/NNP/Input.py", line 92, in eval_inputs
    read_input = read_data(filename_queue)
  File "/home/zan/Desktop/NNP/Input.py", line 32, in read_data
    result.key, value = reader.read(filename_queue)
  File "/usr/local/lib/python2.7/dist-packages/tensorflow/python/ops/io_ops.py", line 334, in read
    return gen_io_ops._reader_read(self._reader_ref, queue_ref, name=name)
  File "/usr/local/lib/python2.7/dist-packages/tensorflow/python/ops/gen_io_ops.py", line 176, in _reader_read
    queue_handle=queue_handle, name=name)
  File "/usr/local/lib/python2.7/dist-packages/tensorflow/python/framework/op_def_library.py", line 703, in apply_op
    op_def=op_def)
  File "/usr/local/lib/python2.7/dist-packages/tensorflow/python/framework/ops.py", line 2310, in create_op
    original_op=self._default_original_op, op_def=op_def)
  File "/usr/local/lib/python2.7/dist-packages/tensorflow/python/framework/ops.py", line 1232, in __init__
    self._traceback = _extract_stack()


Exception in thread Thread-7:
Traceback (most recent call last):
  File "/usr/lib/python2.7/threading.py", line 801, in __bootstrap_inner
    self.run()
  File "/usr/lib/python2.7/threading.py", line 754, in run
    self.__target(*self.__args, **self.__kwargs)
  File "/usr/local/lib/python2.7/dist-packages/tensorflow/python/training/queue_runner.py", line 185, in _run
    sess.run(enqueue_op)
  File "/usr/local/lib/python2.7/dist-packages/tensorflow/python/client/session.py", line 382, in run
    run_metadata_ptr)
  File "/usr/local/lib/python2.7/dist-packages/tensorflow/python/client/session.py", line 655, in _run
    feed_dict_string, options, run_metadata)
  File "/usr/local/lib/python2.7/dist-packages/tensorflow/python/client/session.py", line 723, in _do_run
    target_list, options, run_metadata)
  File "/usr/local/lib/python2.7/dist-packages/tensorflow/python/client/session.py", line 743, in _do_call
    raise type(e)(node_def, op, message)
NotFoundError: /home/zan/Desktop/NNP/Prostate_Cancer_Data1.bin
	 [[Node: ReaderRead = ReaderRead[_class=["loc:@FixedLengthRecordReader", "loc:@input_producer"], _device="/job:localhost/replica:0/task:0/cpu:0"](FixedLengthRecordReader, input_producer)]]
	 [[Node: Slice_1/_9 = _Recv[client_terminated=false, recv_device="/job:localhost/replica:0/task:0/gpu:0", send_device="/job:localhost/replica:0/task:0/cpu:0", send_device_incarnation=1, tensor_name="edge_9_Slice_1", tensor_type=DT_UINT8, _device="/job:localhost/replica:0/task:0/gpu:0"]()]]
Caused by op u'ReaderRead', defined at:
  File "eval.py", line 33, in <module>
    tf.app.run()
  File "/usr/local/lib/python2.7/dist-packages/tensorflow/python/platform/app.py", line 30, in run
    sys.exit(main(sys.argv))
  File "eval.py", line 30, in main
    evaluate()
  File "eval.py", line 13, in evaluate
    images, labels = Process.eval_inputs()
  File "/home/zan/Desktop/NNP/Process.py", line 35, in eval_inputs
    images, labels = Input.eval_inputs(data_dir = data_dir, batch_size = 1)
  File "/home/zan/Desktop/NNP/Input.py", line 92, in eval_inputs
    read_input = read_data(filename_queue)
  File "/home/zan/Desktop/NNP/Input.py", line 32, in read_data
    result.key, value = reader.read(filename_queue)
  File "/usr/local/lib/python2.7/dist-packages/tensorflow/python/ops/io_ops.py", line 334, in read
    return gen_io_ops._reader_read(self._reader_ref, queue_ref, name=name)
  File "/usr/local/lib/python2.7/dist-packages/tensorflow/python/ops/gen_io_ops.py", line 176, in _reader_read
    queue_handle=queue_handle, name=name)
  File "/usr/local/lib/python2.7/dist-packages/tensorflow/python/framework/op_def_library.py", line 703, in apply_op
    op_def=op_def)
  File "/usr/local/lib/python2.7/dist-packages/tensorflow/python/framework/ops.py", line 2310, in create_op
    original_op=self._default_original_op, op_def=op_def)
  File "/usr/local/lib/python2.7/dist-packages/tensorflow/python/framework/ops.py", line 1232, in __init__
    self._traceback = _extract_stack()

ERROR:tensorflow:Exception in QueueRunner: /home/zan/Desktop/NNP/Prostate_Cancer_Data1.bin
	 [[Node: ReaderRead = ReaderRead[_class=["loc:@FixedLengthRecordReader", "loc:@input_producer"], _device="/job:localhost/replica:0/task:0/cpu:0"](FixedLengthRecordReader, input_producer)]]
	 [[Node: Slice/_11 = _Recv[client_terminated=false, recv_device="/job:localhost/replica:0/task:0/gpu:0", send_device="/job:localhost/replica:0/task:0/cpu:0", send_device_incarnation=1, tensor_name="edge_17_Slice", tensor_type=DT_UINT8, _device="/job:localhost/replica:0/task:0/gpu:0"]()]]
Caused by op u'ReaderRead', defined at:
  File "eval.py", line 33, in <module>
    tf.app.run()
  File "/usr/local/lib/python2.7/dist-packages/tensorflow/python/platform/app.py", line 30, in run
    sys.exit(main(sys.argv))
  File "eval.py", line 30, in main
    evaluate()
  File "eval.py", line 13, in evaluate
    images, labels = Process.eval_inputs()
  File "/home/zan/Desktop/NNP/Process.py", line 35, in eval_inputs
    images, labels = Input.eval_inputs(data_dir = data_dir, batch_size = 1)
  File "/home/zan/Desktop/NNP/Input.py", line 92, in eval_inputs
    read_input = read_data(filename_queue)
  File "/home/zan/Desktop/NNP/Input.py", line 32, in read_data
    result.key, value = reader.read(filename_queue)
  File "/usr/local/lib/python2.7/dist-packages/tensorflow/python/ops/io_ops.py", line 334, in read
    return gen_io_ops._reader_read(self._reader_ref, queue_ref, name=name)
  File "/usr/local/lib/python2.7/dist-packages/tensorflow/python/ops/gen_io_ops.py", line 176, in _reader_read
    queue_handle=queue_handle, name=name)
  File "/usr/local/lib/python2.7/dist-packages/tensorflow/python/framework/op_def_library.py", line 703, in apply_op
    op_def=op_def)
  File "/usr/local/lib/python2.7/dist-packages/tensorflow/python/framework/ops.py", line 2310, in create_op
    original_op=self._default_original_op, op_def=op_def)
  File "/usr/local/lib/python2.7/dist-packages/tensorflow/python/framework/ops.py", line 1232, in __init__
    self._traceback = _extract_stack()


Exception in thread Thread-8:
Traceback (most recent call last):
  File "/usr/lib/python2.7/threading.py", line 801, in __bootstrap_inner
    self.run()
  File "/usr/lib/python2.7/threading.py", line 754, in run
    self.__target(*self.__args, **self.__kwargs)
  File "/usr/local/lib/python2.7/dist-packages/tensorflow/python/training/queue_runner.py", line 185, in _run
    sess.run(enqueue_op)
  File "/usr/local/lib/python2.7/dist-packages/tensorflow/python/client/session.py", line 382, in run
    run_metadata_ptr)
  File "/usr/local/lib/python2.7/dist-packages/tensorflow/python/client/session.py", line 655, in _run
    feed_dict_string, options, run_metadata)
  File "/usr/local/lib/python2.7/dist-packages/tensorflow/python/client/session.py", line 723, in _do_run
    target_list, options, run_metadata)
  File "/usr/local/lib/python2.7/dist-packages/tensorflow/python/client/session.py", line 743, in _do_call
    raise type(e)(node_def, op, message)
NotFoundError: /home/zan/Desktop/NNP/Prostate_Cancer_Data1.bin
	 [[Node: ReaderRead = ReaderRead[_class=["loc:@FixedLengthRecordReader", "loc:@input_producer"], _device="/job:localhost/replica:0/task:0/cpu:0"](FixedLengthRecordReader, input_producer)]]
	 [[Node: Slice/_11 = _Recv[client_terminated=false, recv_device="/job:localhost/replica:0/task:0/gpu:0", send_device="/job:localhost/replica:0/task:0/cpu:0", send_device_incarnation=1, tensor_name="edge_17_Slice", tensor_type=DT_UINT8, _device="/job:localhost/replica:0/task:0/gpu:0"]()]]
Caused by op u'ReaderRead', defined at:
  File "eval.py", line 33, in <module>
    tf.app.run()
  File "/usr/local/lib/python2.7/dist-packages/tensorflow/python/platform/app.py", line 30, in run
    sys.exit(main(sys.argv))
  File "eval.py", line 30, in main
    evaluate()
  File "eval.py", line 13, in evaluate
    images, labels = Process.eval_inputs()
  File "/home/zan/Desktop/NNP/Process.py", line 35, in eval_inputs
    images, labels = Input.eval_inputs(data_dir = data_dir, batch_size = 1)
  File "/home/zan/Desktop/NNP/Input.py", line 92, in eval_inputs
    read_input = read_data(filename_queue)
  File "/home/zan/Desktop/NNP/Input.py", line 32, in read_data
    result.key, value = reader.read(filename_queue)
  File "/usr/local/lib/python2.7/dist-packages/tensorflow/python/ops/io_ops.py", line 334, in read
    return gen_io_ops._reader_read(self._reader_ref, queue_ref, name=name)
  File "/usr/local/lib/python2.7/dist-packages/tensorflow/python/ops/gen_io_ops.py", line 176, in _reader_read
    queue_handle=queue_handle, name=name)
  File "/usr/local/lib/python2.7/dist-packages/tensorflow/python/framework/op_def_library.py", line 703, in apply_op
    op_def=op_def)
  File "/usr/local/lib/python2.7/dist-packages/tensorflow/python/framework/ops.py", line 2310, in create_op
    original_op=self._default_original_op, op_def=op_def)
  File "/usr/local/lib/python2.7/dist-packages/tensorflow/python/framework/ops.py", line 1232, in __init__
    self._traceback = _extract_stack()


Exception in thread Thread-5:
Traceback (most recent call last):
  File "/usr/lib/python2.7/threading.py", line 801, in __bootstrap_inner
    self.run()
  File "/usr/lib/python2.7/threading.py", line 754, in run
    self.__target(*self.__args, **self.__kwargs)
  File "/usr/local/lib/python2.7/dist-packages/tensorflow/python/training/queue_runner.py", line 185, in _run
    sess.run(enqueue_op)
  File "/usr/local/lib/python2.7/dist-packages/tensorflow/python/client/session.py", line 382, in run
    run_metadata_ptr)
  File "/usr/local/lib/python2.7/dist-packages/tensorflow/python/client/session.py", line 655, in _run
    feed_dict_string, options, run_metadata)
  File "/usr/local/lib/python2.7/dist-packages/tensorflow/python/client/session.py", line 723, in _do_run
    target_list, options, run_metadata)
  File "/usr/local/lib/python2.7/dist-packages/tensorflow/python/client/session.py", line 743, in _do_call
    raise type(e)(node_def, op, message)
NotFoundError: /home/zan/Desktop/NNP/Prostate_Cancer_Data1.bin
	 [[Node: ReaderRead = ReaderRead[_class=["loc:@FixedLengthRecordReader", "loc:@input_producer"], _device="/job:localhost/replica:0/task:0/cpu:0"](FixedLengthRecordReader, input_producer)]]
	 [[Node: Slice_1/_9 = _Recv[client_terminated=false, recv_device="/job:localhost/replica:0/task:0/gpu:0", send_device="/job:localhost/replica:0/task:0/cpu:0", send_device_incarnation=1, tensor_name="edge_9_Slice_1", tensor_type=DT_UINT8, _device="/job:localhost/replica:0/task:0/gpu:0"]()]]
Caused by op u'ReaderRead', defined at:
  File "eval.py", line 33, in <module>
    tf.app.run()
  File "/usr/local/lib/python2.7/dist-packages/tensorflow/python/platform/app.py", line 30, in run
    sys.exit(main(sys.argv))
  File "eval.py", line 30, in main
    evaluate()
  File "eval.py", line 13, in evaluate
    images, labels = Process.eval_inputs()
  File "/home/zan/Desktop/NNP/Process.py", line 35, in eval_inputs
    images, labels = Input.eval_inputs(data_dir = data_dir, batch_size = 1)
  File "/home/zan/Desktop/NNP/Input.py", line 92, in eval_inputs
    read_input = read_data(filename_queue)
  File "/home/zan/Desktop/NNP/Input.py", line 32, in read_data
    result.key, value = reader.read(filename_queue)
  File "/usr/local/lib/python2.7/dist-packages/tensorflow/python/ops/io_ops.py", line 334, in read
    return gen_io_ops._reader_read(self._reader_ref, queue_ref, name=name)
  File "/usr/local/lib/python2.7/dist-packages/tensorflow/python/ops/gen_io_ops.py", line 176, in _reader_read
    queue_handle=queue_handle, name=name)
  File "/usr/local/lib/python2.7/dist-packages/tensorflow/python/framework/op_def_library.py", line 703, in apply_op
    op_def=op_def)
  File "/usr/local/lib/python2.7/dist-packages/tensorflow/python/framework/ops.py", line 2310, in create_op
    original_op=self._default_original_op, op_def=op_def)
  File "/usr/local/lib/python2.7/dist-packages/tensorflow/python/framework/ops.py", line 1232, in __init__
    self._traceback = _extract_stack()


Exception in thread Thread-4:
Traceback (most recent call last):
  File "/usr/lib/python2.7/threading.py", line 801, in __bootstrap_inner
    self.run()
  File "/usr/lib/python2.7/threading.py", line 754, in run
    self.__target(*self.__args, **self.__kwargs)
  File "/usr/local/lib/python2.7/dist-packages/tensorflow/python/training/queue_runner.py", line 185, in _run
    sess.run(enqueue_op)
  File "/usr/local/lib/python2.7/dist-packages/tensorflow/python/client/session.py", line 382, in run
    run_metadata_ptr)
  File "/usr/local/lib/python2.7/dist-packages/tensorflow/python/client/session.py", line 655, in _run
    feed_dict_string, options, run_metadata)
  File "/usr/local/lib/python2.7/dist-packages/tensorflow/python/client/session.py", line 723, in _do_run
    target_list, options, run_metadata)
  File "/usr/local/lib/python2.7/dist-packages/tensorflow/python/client/session.py", line 743, in _do_call
    raise type(e)(node_def, op, message)
NotFoundError: /home/zan/Desktop/NNP/Prostate_Cancer_Data1.bin
	 [[Node: ReaderRead = ReaderRead[_class=["loc:@FixedLengthRecordReader", "loc:@input_producer"], _device="/job:localhost/replica:0/task:0/cpu:0"](FixedLengthRecordReader, input_producer)]]
	 [[Node: Slice/_11 = _Recv[client_terminated=false, recv_device="/job:localhost/replica:0/task:0/gpu:0", send_device="/job:localhost/replica:0/task:0/cpu:0", send_device_incarnation=1, tensor_name="edge_17_Slice", tensor_type=DT_UINT8, _device="/job:localhost/replica:0/task:0/gpu:0"]()]]
Caused by op u'ReaderRead', defined at:
  File "eval.py", line 33, in <module>
    tf.app.run()
  File "/usr/local/lib/python2.7/dist-packages/tensorflow/python/platform/app.py", line 30, in run
    sys.exit(main(sys.argv))
  File "eval.py", line 30, in main
    evaluate()
  File "eval.py", line 13, in evaluate
    images, labels = Process.eval_inputs()
  File "/home/zan/Desktop/NNP/Process.py", line 35, in eval_inputs
    images, labels = Input.eval_inputs(data_dir = data_dir, batch_size = 1)
  File "/home/zan/Desktop/NNP/Input.py", line 92, in eval_inputs
    read_input = read_data(filename_queue)
  File "/home/zan/Desktop/NNP/Input.py", line 32, in read_data
    result.key, value = reader.read(filename_queue)
  File "/usr/local/lib/python2.7/dist-packages/tensorflow/python/ops/io_ops.py", line 334, in read
    return gen_io_ops._reader_read(self._reader_ref, queue_ref, name=name)
  File "/usr/local/lib/python2.7/dist-packages/tensorflow/python/ops/gen_io_ops.py", line 176, in _reader_read
    queue_handle=queue_handle, name=name)
  File "/usr/local/lib/python2.7/dist-packages/tensorflow/python/framework/op_def_library.py", line 703, in apply_op
    op_def=op_def)
  File "/usr/local/lib/python2.7/dist-packages/tensorflow/python/framework/ops.py", line 2310, in create_op
    original_op=self._default_original_op, op_def=op_def)
  File "/usr/local/lib/python2.7/dist-packages/tensorflow/python/framework/ops.py", line 1232, in __init__
    self._traceback = _extract_stack()


W tensorflow/core/util/tensor_slice_reader.cc:95] Could not open /home/zan/Desktop/NNP/model.ckpt/checkpoint: Data loss: not an sstable (bad magic number): perhaps your file is in a different file format and you need to use a different restore operator?
W tensorflow/core/util/tensor_slice_reader.cc:95] Could not open /home/zan/Desktop/NNP/model.ckpt/checkpoint: Data loss: not an sstable (bad magic number): perhaps your file is in a different file format and you need to use a different restore operator?
W tensorflow/core/framework/op_kernel.cc:936] Data loss: Unable to open table file /home/zan/Desktop/NNP/model.ckpt/checkpoint: Data loss: not an sstable (bad magic number): perhaps your file is in a different file format and you need to use a different restore operator?
W tensorflow/core/util/tensor_slice_reader.cc:95] Could not open /home/zan/Desktop/NNP/model.ckpt/checkpoint: Data loss: not an sstable (bad magic number): perhaps your file is in a different file format and you need to use a different restore operator?
W tensorflow/core/util/tensor_slice_reader.cc:95] Could not open /home/zan/Desktop/NNP/model.ckpt/checkpoint: Data loss: not an sstable (bad magic number): perhaps your file is in a different file format and you need to use a different restore operator?
W tensorflow/core/util/tensor_slice_reader.cc:95] Could not open /home/zan/Desktop/NNP/model.ckpt/checkpoint: Data loss: not an sstable (bad magic number): perhaps your file is in a different file format and you need to use a different restore operator?
W tensorflow/core/framework/op_kernel.cc:936] Data loss: Unable to open table file /home/zan/Desktop/NNP/model.ckpt/checkpoint: Data loss: not an sstable (bad magic number): perhaps your file is in a different file format and you need to use a different restore operator?
W tensorflow/core/util/tensor_slice_reader.cc:95] Could not open /home/zan/Desktop/NNP/model.ckpt/checkpoint: Data loss: not an sstable (bad magic number): perhaps your file is in a different file format and you need to use a different restore operator?
W tensorflow/core/framework/op_kernel.cc:936] Data loss: Unable to open table file /home/zan/Desktop/NNP/model.ckpt/checkpoint: Data loss: not an sstable (bad magic number): perhaps your file is in a different file format and you need to use a different restore operator?
W tensorflow/core/util/tensor_slice_reader.cc:95] Could not open /home/zan/Desktop/NNP/model.ckpt/checkpoint: Data loss: not an sstable (bad magic number): perhaps your file is in a different file format and you need to use a different restore operator?
W tensorflow/core/util/tensor_slice_reader.cc:95] Could not open /home/zan/Desktop/NNP/model.ckpt/checkpoint: Data loss: not an sstable (bad magic number): perhaps your file is in a different file format and you need to use a different restore operator?
W tensorflow/core/framework/op_kernel.cc:936] Data loss: Unable to open table file /home/zan/Desktop/NNP/model.ckpt/checkpoint: Data loss: not an sstable (bad magic number): perhaps your file is in a different file format and you need to use a different restore operator?
W tensorflow/core/util/tensor_slice_reader.cc:95] Could not open /home/zan/Desktop/NNP/model.ckpt/checkpoint: Data loss: not an sstable (bad magic number): perhaps your file is in a different file format and you need to use a different restore operator?
W tensorflow/core/util/tensor_slice_reader.cc:95] Could not open /home/zan/Desktop/NNP/model.ckpt/checkpoint: Data loss: not an sstable (bad magic number): perhaps your file is in a different file format and you need to use a different restore operator?
W tensorflow/core/util/tensor_slice_reader.cc:95] Could not open /home/zan/Desktop/NNP/model.ckpt/checkpoint: Data loss: not an sstable (bad magic number): perhaps your file is in a different file format and you need to use a different restore operator?
W tensorflow/core/framework/op_kernel.cc:936] Data loss: Unable to open table file /home/zan/Desktop/NNP/model.ckpt/checkpoint: Data loss: not an sstable (bad magic number): perhaps your file is in a different file format and you need to use a different restore operator?
W tensorflow/core/util/tensor_slice_reader.cc:95] Could not open /home/zan/Desktop/NNP/model.ckpt/checkpoint: Data loss: not an sstable (bad magic number): perhaps your file is in a different file format and you need to use a different restore operator?
W tensorflow/core/framework/op_kernel.cc:936] Data loss: Unable to open table file /home/zan/Desktop/NNP/model.ckpt/checkpoint: Data loss: not an sstable (bad magic number): perhaps your file is in a different file format and you need to use a different restore operator?
W tensorflow/core/util/tensor_slice_reader.cc:95] Could not open /home/zan/Desktop/NNP/model.ckpt/checkpoint: Data loss: not an sstable (bad magic number): perhaps your file is in a different file format and you need to use a different restore operator?
W tensorflow/core/util/tensor_slice_reader.cc:95] Could not open /home/zan/Desktop/NNP/model.ckpt/checkpoint: Data loss: not an sstable (bad magic number): perhaps your file is in a different file format and you need to use a different restore operator?
W tensorflow/core/util/tensor_slice_reader.cc:95] Could not open /home/zan/Desktop/NNP/model.ckpt/checkpoint: Data loss: not an sstable (bad magic number): perhaps your file is in a different file format and you need to use a different restore operator?
W tensorflow/core/framework/op_kernel.cc:936] Data loss: Unable to open table file /home/zan/Desktop/NNP/model.ckpt/checkpoint: Data loss: not an sstable (bad magic number): perhaps your file is in a different file format and you need to use a different restore operator?
W tensorflow/core/util/tensor_slice_reader.cc:95] Could not open /home/zan/Desktop/NNP/model.ckpt/checkpoint: Data loss: not an sstable (bad magic number): perhaps your file is in a different file format and you need to use a different restore operator?
W tensorflow/core/framework/op_kernel.cc:936] Data loss: Unable to open table file /home/zan/Desktop/NNP/model.ckpt/checkpoint: Data loss: not an sstable (bad magic number): perhaps your file is in a different file format and you need to use a different restore operator?
W tensorflow/core/util/tensor_slice_reader.cc:95] Could not open /home/zan/Desktop/NNP/model.ckpt/checkpoint: Data loss: not an sstable (bad magic number): perhaps your file is in a different file format and you need to use a different restore operator?
W tensorflow/core/util/tensor_slice_reader.cc:95] Could not open /home/zan/Desktop/NNP/model.ckpt/checkpoint: Data loss: not an sstable (bad magic number): perhaps your file is in a different file format and you need to use a different restore operator?
W tensorflow/core/util/tensor_slice_reader.cc:95] Could not open /home/zan/Desktop/NNP/model.ckpt/checkpoint: Data loss: not an sstable (bad magic number): perhaps your file is in a different file format and you need to use a different restore operator?
W tensorflow/core/framework/op_kernel.cc:936] Data loss: Unable to open table file /home/zan/Desktop/NNP/model.ckpt/checkpoint: Data loss: not an sstable (bad magic number): perhaps your file is in a different file format and you need to use a different restore operator?
W tensorflow/core/util/tensor_slice_reader.cc:95] Could not open /home/zan/Desktop/NNP/model.ckpt/checkpoint: Data loss: not an sstable (bad magic number): perhaps your file is in a different file format and you need to use a different restore operator?
W tensorflow/core/framework/op_kernel.cc:936] Data loss: Unable to open table file /home/zan/Desktop/NNP/model.ckpt/checkpoint: Data loss: not an sstable (bad magic number): perhaps your file is in a different file format and you need to use a different restore operator?
W tensorflow/core/util/tensor_slice_reader.cc:95] Could not open /home/zan/Desktop/NNP/model.ckpt/checkpoint: Data loss: not an sstable (bad magic number): perhaps your file is in a different file format and you need to use a different restore operator?
W tensorflow/core/util/tensor_slice_reader.cc:95] Could not open /home/zan/Desktop/NNP/model.ckpt/checkpoint: Data loss: not an sstable (bad magic number): perhaps your file is in a different file format and you need to use a different restore operator?
W tensorflow/core/framework/op_kernel.cc:936] Data loss: Unable to open table file /home/zan/Desktop/NNP/model.ckpt/checkpoint: Data loss: not an sstable (bad magic number): perhaps your file is in a different file format and you need to use a different restore operator?
E tensorflow/core/client/tensor_c_api.cc:485] Unable to open table file /home/zan/Desktop/NNP/model.ckpt/checkpoint: Data loss: not an sstable (bad magic number): perhaps your file is in a different file format and you need to use a different restore operator?
	 [[Node: save/restore_slice = RestoreSlice[dt=DT_FLOAT, preferred_shard=-1, _device="/job:localhost/replica:0/task:0/cpu:0"](_recv_save/Const_0, save/restore_slice/tensor_name, save/restore_slice/shape_and_slice)]]
	 [[Node: save/restore_slice_3/_110 = _Recv[client_terminated=false, recv_device="/job:localhost/replica:0/task:0/gpu:0", send_device="/job:localhost/replica:0/task:0/cpu:0", send_device_incarnation=1, tensor_name="edge_50_save/restore_slice_3", tensor_type=DT_FLOAT, _device="/job:localhost/replica:0/task:0/gpu:0"]()]]
W tensorflow/core/kernels/queue_base.cc:294] _0_input_producer: Skipping cancelled enqueue attempt with queue not closed
E tensorflow/core/client/tensor_c_api.cc:485] Enqueue operation was cancelled
	 [[Node: input_producer/input_producer_EnqueueMany = QueueEnqueueMany[Tcomponents=[DT_STRING], _class=["loc:@input_producer"], timeout_ms=-1, _device="/job:localhost/replica:0/task:0/cpu:0"](input_producer, input_producer/RandomShuffle)]]
Traceback (most recent call last):
  File "eval.py", line 33, in <module>
    tf.app.run()
  File "/usr/local/lib/python2.7/dist-packages/tensorflow/python/platform/app.py", line 30, in run
    sys.exit(main(sys.argv))
  File "eval.py", line 30, in main
    evaluate()
  File "eval.py", line 22, in evaluate
    saver.restore(sess, eval_dir)
  File "/usr/local/lib/python2.7/dist-packages/tensorflow/python/training/saver.py", line 1129, in restore
    {self.saver_def.filename_tensor_name: save_path})
  File "/usr/local/lib/python2.7/dist-packages/tensorflow/python/client/session.py", line 382, in run
    run_metadata_ptr)
  File "/usr/local/lib/python2.7/dist-packages/tensorflow/python/client/session.py", line 655, in _run
    feed_dict_string, options, run_metadata)
  File "/usr/local/lib/python2.7/dist-packages/tensorflow/python/client/session.py", line 723, in _do_run
    target_list, options, run_metadata)
  File "/usr/local/lib/python2.7/dist-packages/tensorflow/python/client/session.py", line 743, in _do_call
    raise type(e)(node_def, op, message)
tensorflow.python.framework.errors.DataLossError: Unable to open table file /home/zan/Desktop/NNP/model.ckpt/checkpoint: Data loss: not an sstable (bad magic number): perhaps your file is in a different file format and you need to use a different restore operator?
	 [[Node: save/restore_slice = RestoreSlice[dt=DT_FLOAT, preferred_shard=-1, _device="/job:localhost/replica:0/task:0/cpu:0"](_recv_save/Const_0, save/restore_slice/tensor_name, save/restore_slice/shape_and_slice)]]
	 [[Node: save/restore_slice_3/_110 = _Recv[client_terminated=false, recv_device="/job:localhost/replica:0/task:0/gpu:0", send_device="/job:localhost/replica:0/task:0/cpu:0", send_device_incarnation=1, tensor_name="edge_50_save/restore_slice_3", tensor_type=DT_FLOAT, _device="/job:localhost/replica:0/task:0/gpu:0"]()]]
Caused by op u'save/restore_slice', defined at:
  File "eval.py", line 33, in <module>
    tf.app.run()
  File "/usr/local/lib/python2.7/dist-packages/tensorflow/python/platform/app.py", line 30, in run
    sys.exit(main(sys.argv))
  File "eval.py", line 30, in main
    evaluate()
  File "eval.py", line 16, in evaluate
    saver = tf.train.Saver()
  File "/usr/local/lib/python2.7/dist-packages/tensorflow/python/training/saver.py", line 861, in __init__
    restore_sequentially=restore_sequentially)
  File "/usr/local/lib/python2.7/dist-packages/tensorflow/python/training/saver.py", line 519, in build
    filename_tensor, vars_to_save, restore_sequentially, reshape)
  File "/usr/local/lib/python2.7/dist-packages/tensorflow/python/training/saver.py", line 272, in _AddRestoreOps
    values = self.restore_op(filename_tensor, vs, preferred_shard)
  File "/usr/local/lib/python2.7/dist-packages/tensorflow/python/training/saver.py", line 187, in restore_op
    preferred_shard=preferred_shard)
  File "/usr/local/lib/python2.7/dist-packages/tensorflow/python/ops/io_ops.py", line 203, in _restore_slice
    preferred_shard, name=name)
  File "/usr/local/lib/python2.7/dist-packages/tensorflow/python/ops/gen_io_ops.py", line 359, in _restore_slice
    preferred_shard=preferred_shard, name=name)
  File "/usr/local/lib/python2.7/dist-packages/tensorflow/python/framework/op_def_library.py", line 703, in apply_op
    op_def=op_def)
  File "/usr/local/lib/python2.7/dist-packages/tensorflow/python/framework/ops.py", line 2310, in create_op
    original_op=self._default_original_op, op_def=op_def)
  File "/usr/local/lib/python2.7/dist-packages/tensorflow/python/framework/ops.py", line 1232, in __init__
    self._traceback = _extract_stack()


